{
 "cells": [
  {
   "cell_type": "code",
   "execution_count": 27,
   "metadata": {
    "collapsed": false
   },
   "outputs": [],
   "source": [
    "import warnings\n",
    "warnings.filterwarnings('ignore')"
   ]
  },
  {
   "cell_type": "code",
   "execution_count": 32,
   "metadata": {},
   "outputs": [],
   "source": [
    "import boto3\n",
    "\n",
    "client = boto3.client(\n",
    "    's3',\n",
    "    aws_access_key_id='ASIAVTR7J6Y6BYPAYIYD',\n",
    "    aws_secret_access_key='QTG/eo8RWvZVuga4qug8TAWRei6kz48o/umsCrHt',\n",
    "    aws_session_token='FwoGZXIvYXdzEOH//////////wEaDHBe3qmRH0v7m591WSLLAYAOBnY8Zs1iFJmuhx+iCJp/G5O0sBJQQhUywwpqoClbzdwJCDfX8vkZfWl02Zno/XK6UVbUUn2VCRJM64jpw6ehwYQv5x8d2iEx3AuK830PzsMYSUZVEbKKJ1N6pCl7V0I14B4u7skiA2VFofs1W4lFdV6hed+emqmAHXjus8aO81w82RQzqG1M937pgm1CV9UYDx5/uUoJ/6k1xYc/2iaHneaAhqb/8LeH/f3qLWHz16k4sM0OsgaJ3jU8eu49bzq8xTV0crES5zLNKJTCuqMGMi3XkozHkDX5nkyzGMYNr2hrSiL1SKznCKNf+/enk9M1j62kEjx8B8aNPbCtaZ4='\n",
    ")"
   ]
  },
  {
   "cell_type": "code",
   "execution_count": 31,
   "metadata": {},
   "outputs": [
    {
     "ename": "ClientError",
     "evalue": "An error occurred (AuthFailure) when calling the RunInstances operation: AWS was not able to validate the provided access credentials",
     "output_type": "error",
     "traceback": [
      "\u001b[0;31m---------------------------------------------------------------------------\u001b[0m",
      "\u001b[0;31mClientError\u001b[0m                               Traceback (most recent call last)",
      "Cell \u001b[0;32mIn[31], line 4\u001b[0m\n\u001b[1;32m      2\u001b[0m ec2 \u001b[38;5;241m=\u001b[39m boto3\u001b[38;5;241m.\u001b[39mclient(\u001b[38;5;124m'\u001b[39m\u001b[38;5;124mec2\u001b[39m\u001b[38;5;124m'\u001b[39m)\n\u001b[1;32m      3\u001b[0m \u001b[38;5;66;03m# Get AMI ID from \"Instance Details\" in EC2 Console\u001b[39;00m\n\u001b[0;32m----> 4\u001b[0m r \u001b[38;5;241m=\u001b[39m \u001b[43mec2\u001b[49m\u001b[38;5;241;43m.\u001b[39;49m\u001b[43mrun_instances\u001b[49m\u001b[43m(\u001b[49m\u001b[43mImageId\u001b[49m\u001b[38;5;241;43m=\u001b[39;49m\u001b[38;5;124;43m'\u001b[39;49m\u001b[38;5;124;43mami-02e136e904f3da870\u001b[39;49m\u001b[38;5;124;43m'\u001b[39;49m\u001b[43m,\u001b[49m\n\u001b[1;32m      5\u001b[0m \u001b[43m                      \u001b[49m\u001b[43mKeyName\u001b[49m\u001b[38;5;241;43m=\u001b[39;49m\u001b[38;5;124;43m'\u001b[39;49m\u001b[38;5;124;43mvockey\u001b[39;49m\u001b[38;5;124;43m'\u001b[39;49m\u001b[43m,\u001b[49m\n\u001b[1;32m      6\u001b[0m \u001b[43m                      \u001b[49m\u001b[43mMaxCount\u001b[49m\u001b[38;5;241;43m=\u001b[39;49m\u001b[38;5;241;43m2\u001b[39;49m\u001b[43m,\u001b[49m\n\u001b[1;32m      7\u001b[0m \u001b[43m                      \u001b[49m\u001b[43mMinCount\u001b[49m\u001b[38;5;241;43m=\u001b[39;49m\u001b[38;5;241;43m1\u001b[39;49m\u001b[43m)\u001b[49m\n\u001b[1;32m      8\u001b[0m ids \u001b[38;5;241m=\u001b[39m [instance[\u001b[38;5;124m'\u001b[39m\u001b[38;5;124mInstanceId\u001b[39m\u001b[38;5;124m'\u001b[39m] \u001b[38;5;28;01mfor\u001b[39;00m instance \u001b[38;5;129;01min\u001b[39;00m r[\u001b[38;5;124m'\u001b[39m\u001b[38;5;124mInstances\u001b[39m\u001b[38;5;124m'\u001b[39m]] \u001b[38;5;66;03m# find Instance ID\u001b[39;00m\n\u001b[1;32m      9\u001b[0m ec2\u001b[38;5;241m.\u001b[39mterminate_instances(InstanceIds\u001b[38;5;241m=\u001b[39mids)\n",
      "File \u001b[0;32m~/opt/anaconda3/lib/python3.9/site-packages/botocore/client.py:530\u001b[0m, in \u001b[0;36mClientCreator._create_api_method.<locals>._api_call\u001b[0;34m(self, *args, **kwargs)\u001b[0m\n\u001b[1;32m    526\u001b[0m     \u001b[39mraise\u001b[39;00m \u001b[39mTypeError\u001b[39;00m(\n\u001b[1;32m    527\u001b[0m         \u001b[39mf\u001b[39m\u001b[39m\"\u001b[39m\u001b[39m{\u001b[39;00mpy_operation_name\u001b[39m}\u001b[39;00m\u001b[39m() only accepts keyword arguments.\u001b[39m\u001b[39m\"\u001b[39m\n\u001b[1;32m    528\u001b[0m     )\n\u001b[1;32m    529\u001b[0m \u001b[39m# The \"self\" in this scope is referring to the BaseClient.\u001b[39;00m\n\u001b[0;32m--> 530\u001b[0m \u001b[39mreturn\u001b[39;00m \u001b[39mself\u001b[39;49m\u001b[39m.\u001b[39;49m_make_api_call(operation_name, kwargs)\n",
      "File \u001b[0;32m~/opt/anaconda3/lib/python3.9/site-packages/botocore/client.py:960\u001b[0m, in \u001b[0;36mBaseClient._make_api_call\u001b[0;34m(self, operation_name, api_params)\u001b[0m\n\u001b[1;32m    958\u001b[0m     error_code \u001b[39m=\u001b[39m parsed_response\u001b[39m.\u001b[39mget(\u001b[39m\"\u001b[39m\u001b[39mError\u001b[39m\u001b[39m\"\u001b[39m, {})\u001b[39m.\u001b[39mget(\u001b[39m\"\u001b[39m\u001b[39mCode\u001b[39m\u001b[39m\"\u001b[39m)\n\u001b[1;32m    959\u001b[0m     error_class \u001b[39m=\u001b[39m \u001b[39mself\u001b[39m\u001b[39m.\u001b[39mexceptions\u001b[39m.\u001b[39mfrom_code(error_code)\n\u001b[0;32m--> 960\u001b[0m     \u001b[39mraise\u001b[39;00m error_class(parsed_response, operation_name)\n\u001b[1;32m    961\u001b[0m \u001b[39melse\u001b[39;00m:\n\u001b[1;32m    962\u001b[0m     \u001b[39mreturn\u001b[39;00m parsed_response\n",
      "\u001b[0;31mClientError\u001b[0m: An error occurred (AuthFailure) when calling the RunInstances operation: AWS was not able to validate the provided access credentials"
     ]
    }
   ],
   "source": [
    "import boto3\n",
    "ec2 = boto3.client('ec2')\n",
    "# Get AMI ID from \"Instance Details\" in EC2 Console\n",
    "r = ec2.run_instances(ImageId='ami-02e136e904f3da870',\n",
    "                      KeyName='vockey',\n",
    "                      MaxCount=2,\n",
    "                      MinCount=1)\n",
    "ids = [instance['InstanceId'] for instance in r['Instances']] # find Instance ID\n",
    "ec2.terminate_instances(InstanceIds=ids)"
   ]
  },
  {
   "cell_type": "code",
   "execution_count": 25,
   "metadata": {},
   "outputs": [
    {
     "ename": "ClientError",
     "evalue": "An error occurred (InvalidAccessKeyId) when calling the CreateBucket operation: The AWS Access Key Id you provided does not exist in our records.",
     "output_type": "error",
     "traceback": [
      "\u001b[0;31m---------------------------------------------------------------------------\u001b[0m",
      "\u001b[0;31mClientError\u001b[0m                               Traceback (most recent call last)",
      "Cell \u001b[0;32mIn[25], line 11\u001b[0m\n\u001b[1;32m      9\u001b[0m s3_resource \u001b[38;5;241m=\u001b[39m boto3\u001b[38;5;241m.\u001b[39mresource(\u001b[38;5;124m'\u001b[39m\u001b[38;5;124ms3\u001b[39m\u001b[38;5;124m'\u001b[39m)\n\u001b[1;32m     10\u001b[0m bucket \u001b[38;5;241m=\u001b[39m \u001b[38;5;124m'\u001b[39m\u001b[38;5;124memrbuckey\u001b[39m\u001b[38;5;124m'\u001b[39m\n\u001b[0;32m---> 11\u001b[0m \u001b[43ms3_resource\u001b[49m\u001b[38;5;241;43m.\u001b[39;49m\u001b[43mcreate_bucket\u001b[49m\u001b[43m(\u001b[49m\u001b[43mBucket\u001b[49m\u001b[38;5;241;43m=\u001b[39;49m\u001b[43mbucket\u001b[49m\u001b[43m)\u001b[49m\n",
      "File \u001b[0;32m~/opt/anaconda3/lib/python3.9/site-packages/boto3/resources/factory.py:580\u001b[0m, in \u001b[0;36mResourceFactory._create_action.<locals>.do_action\u001b[0;34m(self, *args, **kwargs)\u001b[0m\n\u001b[1;32m    579\u001b[0m \u001b[39mdef\u001b[39;00m \u001b[39mdo_action\u001b[39m(\u001b[39mself\u001b[39m, \u001b[39m*\u001b[39margs, \u001b[39m*\u001b[39m\u001b[39m*\u001b[39mkwargs):\n\u001b[0;32m--> 580\u001b[0m     response \u001b[39m=\u001b[39m action(\u001b[39mself\u001b[39;49m, \u001b[39m*\u001b[39;49margs, \u001b[39m*\u001b[39;49m\u001b[39m*\u001b[39;49mkwargs)\n\u001b[1;32m    582\u001b[0m     \u001b[39mif\u001b[39;00m \u001b[39mhasattr\u001b[39m(\u001b[39mself\u001b[39m, \u001b[39m'\u001b[39m\u001b[39mload\u001b[39m\u001b[39m'\u001b[39m):\n\u001b[1;32m    583\u001b[0m         \u001b[39m# Clear cached data. It will be reloaded the next\u001b[39;00m\n\u001b[1;32m    584\u001b[0m         \u001b[39m# time that an attribute is accessed.\u001b[39;00m\n\u001b[1;32m    585\u001b[0m         \u001b[39m# TODO: Make this configurable in the future?\u001b[39;00m\n\u001b[1;32m    586\u001b[0m         \u001b[39mself\u001b[39m\u001b[39m.\u001b[39mmeta\u001b[39m.\u001b[39mdata \u001b[39m=\u001b[39m \u001b[39mNone\u001b[39;00m\n",
      "File \u001b[0;32m~/opt/anaconda3/lib/python3.9/site-packages/boto3/resources/action.py:88\u001b[0m, in \u001b[0;36mServiceAction.__call__\u001b[0;34m(self, parent, *args, **kwargs)\u001b[0m\n\u001b[1;32m     79\u001b[0m params\u001b[39m.\u001b[39mupdate(kwargs)\n\u001b[1;32m     81\u001b[0m logger\u001b[39m.\u001b[39mdebug(\n\u001b[1;32m     82\u001b[0m     \u001b[39m'\u001b[39m\u001b[39mCalling \u001b[39m\u001b[39m%s\u001b[39;00m\u001b[39m:\u001b[39m\u001b[39m%s\u001b[39;00m\u001b[39m with \u001b[39m\u001b[39m%r\u001b[39;00m\u001b[39m'\u001b[39m,\n\u001b[1;32m     83\u001b[0m     parent\u001b[39m.\u001b[39mmeta\u001b[39m.\u001b[39mservice_name,\n\u001b[1;32m     84\u001b[0m     operation_name,\n\u001b[1;32m     85\u001b[0m     params,\n\u001b[1;32m     86\u001b[0m )\n\u001b[0;32m---> 88\u001b[0m response \u001b[39m=\u001b[39m \u001b[39mgetattr\u001b[39;49m(parent\u001b[39m.\u001b[39;49mmeta\u001b[39m.\u001b[39;49mclient, operation_name)(\u001b[39m*\u001b[39;49margs, \u001b[39m*\u001b[39;49m\u001b[39m*\u001b[39;49mparams)\n\u001b[1;32m     90\u001b[0m logger\u001b[39m.\u001b[39mdebug(\u001b[39m'\u001b[39m\u001b[39mResponse: \u001b[39m\u001b[39m%r\u001b[39;00m\u001b[39m'\u001b[39m, response)\n\u001b[1;32m     92\u001b[0m \u001b[39mreturn\u001b[39;00m \u001b[39mself\u001b[39m\u001b[39m.\u001b[39m_response_handler(parent, params, response)\n",
      "File \u001b[0;32m~/opt/anaconda3/lib/python3.9/site-packages/botocore/client.py:530\u001b[0m, in \u001b[0;36mClientCreator._create_api_method.<locals>._api_call\u001b[0;34m(self, *args, **kwargs)\u001b[0m\n\u001b[1;32m    526\u001b[0m     \u001b[39mraise\u001b[39;00m \u001b[39mTypeError\u001b[39;00m(\n\u001b[1;32m    527\u001b[0m         \u001b[39mf\u001b[39m\u001b[39m\"\u001b[39m\u001b[39m{\u001b[39;00mpy_operation_name\u001b[39m}\u001b[39;00m\u001b[39m() only accepts keyword arguments.\u001b[39m\u001b[39m\"\u001b[39m\n\u001b[1;32m    528\u001b[0m     )\n\u001b[1;32m    529\u001b[0m \u001b[39m# The \"self\" in this scope is referring to the BaseClient.\u001b[39;00m\n\u001b[0;32m--> 530\u001b[0m \u001b[39mreturn\u001b[39;00m \u001b[39mself\u001b[39;49m\u001b[39m.\u001b[39;49m_make_api_call(operation_name, kwargs)\n",
      "File \u001b[0;32m~/opt/anaconda3/lib/python3.9/site-packages/botocore/client.py:960\u001b[0m, in \u001b[0;36mBaseClient._make_api_call\u001b[0;34m(self, operation_name, api_params)\u001b[0m\n\u001b[1;32m    958\u001b[0m     error_code \u001b[39m=\u001b[39m parsed_response\u001b[39m.\u001b[39mget(\u001b[39m\"\u001b[39m\u001b[39mError\u001b[39m\u001b[39m\"\u001b[39m, {})\u001b[39m.\u001b[39mget(\u001b[39m\"\u001b[39m\u001b[39mCode\u001b[39m\u001b[39m\"\u001b[39m)\n\u001b[1;32m    959\u001b[0m     error_class \u001b[39m=\u001b[39m \u001b[39mself\u001b[39m\u001b[39m.\u001b[39mexceptions\u001b[39m.\u001b[39mfrom_code(error_code)\n\u001b[0;32m--> 960\u001b[0m     \u001b[39mraise\u001b[39;00m error_class(parsed_response, operation_name)\n\u001b[1;32m    961\u001b[0m \u001b[39melse\u001b[39;00m:\n\u001b[1;32m    962\u001b[0m     \u001b[39mreturn\u001b[39;00m parsed_response\n",
      "\u001b[0;31mClientError\u001b[0m: An error occurred (InvalidAccessKeyId) when calling the CreateBucket operation: The AWS Access Key Id you provided does not exist in our records."
     ]
    }
   ],
   "source": [
    "import boto3\n",
    "\n",
    "s3 = boto3.client('s3',\n",
    "aws_access_key_id='ASIAVTR7J6Y6BYPAYIYD',\n",
    "                        aws_secret_access_key='QTG/eo8RWvZVuga4qug8TAWRei6kz48o/umsCrHt',\n",
    "                        aws_session_token='FwoGZXIvYXdzEOH//////////wEaDHBe3qmRH0v7m591WSLLAYAOBnY8Zs1iFJmuhx+iCJp/G5O0sBJQQhUywwpqoClbzdwJCDfX8vkZfWl02Zno/XK6UVbUUn2VCRJM64jpw6ehwYQv5x8d2iEx3AuK830PzsMYSUZVEbKKJ1N6pCl7V0I14B4u7skiA2VFofs1W4lFdV6hed+emqmAHXjus8aO81w82RQzqG1M937pgm1CV9UYDx5/uUoJ/6k1xYc/2iaHneaAhqb/8LeH/f3qLWHz16k4sM0OsgaJ3jU8eu49bzq8xTV0crES5zLNKJTCuqMGMi3XkozHkDX5nkyzGMYNr2hrSiL1SKznCKNf+/enk9M1j62kEjx8B8aNPbCtaZ4=',\n",
    "                        region_name='us-east-1'\n",
    ")\n",
    "s3_resource = boto3.resource('s3')\n",
    "bucket = 'emrbuckey'\n",
    "s3_resource.create_bucket(Bucket=bucket)"
   ]
  },
  {
   "cell_type": "code",
   "execution_count": 22,
   "metadata": {
    "collapsed": true
   },
   "outputs": [
    {
     "ename": "ClientError",
     "evalue": "An error occurred (InvalidAccessKeyId) when calling the CreateBucket operation: The AWS Access Key Id you provided does not exist in our records.",
     "output_type": "error",
     "traceback": [
      "\u001b[0;31m---------------------------------------------------------------------------\u001b[0m",
      "\u001b[0;31mClientError\u001b[0m                               Traceback (most recent call last)",
      "Cell \u001b[0;32mIn[22], line 5\u001b[0m\n\u001b[1;32m      3\u001b[0m s3_resource \u001b[38;5;241m=\u001b[39m boto3\u001b[38;5;241m.\u001b[39mresource(\u001b[38;5;124m'\u001b[39m\u001b[38;5;124ms3\u001b[39m\u001b[38;5;124m'\u001b[39m)\n\u001b[1;32m      4\u001b[0m bucket \u001b[38;5;241m=\u001b[39m \u001b[38;5;124m'\u001b[39m\u001b[38;5;124memrbuckey\u001b[39m\u001b[38;5;124m'\u001b[39m\n\u001b[0;32m----> 5\u001b[0m \u001b[43ms3_resource\u001b[49m\u001b[38;5;241;43m.\u001b[39;49m\u001b[43mcreate_bucket\u001b[49m\u001b[43m(\u001b[49m\u001b[43mBucket\u001b[49m\u001b[38;5;241;43m=\u001b[39;49m\u001b[43mbucket\u001b[49m\u001b[43m)\u001b[49m\n",
      "File \u001b[0;32m~/opt/anaconda3/lib/python3.9/site-packages/boto3/resources/factory.py:580\u001b[0m, in \u001b[0;36mResourceFactory._create_action.<locals>.do_action\u001b[0;34m(self, *args, **kwargs)\u001b[0m\n\u001b[1;32m    579\u001b[0m \u001b[39mdef\u001b[39;00m \u001b[39mdo_action\u001b[39m(\u001b[39mself\u001b[39m, \u001b[39m*\u001b[39margs, \u001b[39m*\u001b[39m\u001b[39m*\u001b[39mkwargs):\n\u001b[0;32m--> 580\u001b[0m     response \u001b[39m=\u001b[39m action(\u001b[39mself\u001b[39;49m, \u001b[39m*\u001b[39;49margs, \u001b[39m*\u001b[39;49m\u001b[39m*\u001b[39;49mkwargs)\n\u001b[1;32m    582\u001b[0m     \u001b[39mif\u001b[39;00m \u001b[39mhasattr\u001b[39m(\u001b[39mself\u001b[39m, \u001b[39m'\u001b[39m\u001b[39mload\u001b[39m\u001b[39m'\u001b[39m):\n\u001b[1;32m    583\u001b[0m         \u001b[39m# Clear cached data. It will be reloaded the next\u001b[39;00m\n\u001b[1;32m    584\u001b[0m         \u001b[39m# time that an attribute is accessed.\u001b[39;00m\n\u001b[1;32m    585\u001b[0m         \u001b[39m# TODO: Make this configurable in the future?\u001b[39;00m\n\u001b[1;32m    586\u001b[0m         \u001b[39mself\u001b[39m\u001b[39m.\u001b[39mmeta\u001b[39m.\u001b[39mdata \u001b[39m=\u001b[39m \u001b[39mNone\u001b[39;00m\n",
      "File \u001b[0;32m~/opt/anaconda3/lib/python3.9/site-packages/boto3/resources/action.py:88\u001b[0m, in \u001b[0;36mServiceAction.__call__\u001b[0;34m(self, parent, *args, **kwargs)\u001b[0m\n\u001b[1;32m     79\u001b[0m params\u001b[39m.\u001b[39mupdate(kwargs)\n\u001b[1;32m     81\u001b[0m logger\u001b[39m.\u001b[39mdebug(\n\u001b[1;32m     82\u001b[0m     \u001b[39m'\u001b[39m\u001b[39mCalling \u001b[39m\u001b[39m%s\u001b[39;00m\u001b[39m:\u001b[39m\u001b[39m%s\u001b[39;00m\u001b[39m with \u001b[39m\u001b[39m%r\u001b[39;00m\u001b[39m'\u001b[39m,\n\u001b[1;32m     83\u001b[0m     parent\u001b[39m.\u001b[39mmeta\u001b[39m.\u001b[39mservice_name,\n\u001b[1;32m     84\u001b[0m     operation_name,\n\u001b[1;32m     85\u001b[0m     params,\n\u001b[1;32m     86\u001b[0m )\n\u001b[0;32m---> 88\u001b[0m response \u001b[39m=\u001b[39m \u001b[39mgetattr\u001b[39;49m(parent\u001b[39m.\u001b[39;49mmeta\u001b[39m.\u001b[39;49mclient, operation_name)(\u001b[39m*\u001b[39;49margs, \u001b[39m*\u001b[39;49m\u001b[39m*\u001b[39;49mparams)\n\u001b[1;32m     90\u001b[0m logger\u001b[39m.\u001b[39mdebug(\u001b[39m'\u001b[39m\u001b[39mResponse: \u001b[39m\u001b[39m%r\u001b[39;00m\u001b[39m'\u001b[39m, response)\n\u001b[1;32m     92\u001b[0m \u001b[39mreturn\u001b[39;00m \u001b[39mself\u001b[39m\u001b[39m.\u001b[39m_response_handler(parent, params, response)\n",
      "File \u001b[0;32m~/opt/anaconda3/lib/python3.9/site-packages/botocore/client.py:530\u001b[0m, in \u001b[0;36mClientCreator._create_api_method.<locals>._api_call\u001b[0;34m(self, *args, **kwargs)\u001b[0m\n\u001b[1;32m    526\u001b[0m     \u001b[39mraise\u001b[39;00m \u001b[39mTypeError\u001b[39;00m(\n\u001b[1;32m    527\u001b[0m         \u001b[39mf\u001b[39m\u001b[39m\"\u001b[39m\u001b[39m{\u001b[39;00mpy_operation_name\u001b[39m}\u001b[39;00m\u001b[39m() only accepts keyword arguments.\u001b[39m\u001b[39m\"\u001b[39m\n\u001b[1;32m    528\u001b[0m     )\n\u001b[1;32m    529\u001b[0m \u001b[39m# The \"self\" in this scope is referring to the BaseClient.\u001b[39;00m\n\u001b[0;32m--> 530\u001b[0m \u001b[39mreturn\u001b[39;00m \u001b[39mself\u001b[39;49m\u001b[39m.\u001b[39;49m_make_api_call(operation_name, kwargs)\n",
      "File \u001b[0;32m~/opt/anaconda3/lib/python3.9/site-packages/botocore/client.py:960\u001b[0m, in \u001b[0;36mBaseClient._make_api_call\u001b[0;34m(self, operation_name, api_params)\u001b[0m\n\u001b[1;32m    958\u001b[0m     error_code \u001b[39m=\u001b[39m parsed_response\u001b[39m.\u001b[39mget(\u001b[39m\"\u001b[39m\u001b[39mError\u001b[39m\u001b[39m\"\u001b[39m, {})\u001b[39m.\u001b[39mget(\u001b[39m\"\u001b[39m\u001b[39mCode\u001b[39m\u001b[39m\"\u001b[39m)\n\u001b[1;32m    959\u001b[0m     error_class \u001b[39m=\u001b[39m \u001b[39mself\u001b[39m\u001b[39m.\u001b[39mexceptions\u001b[39m.\u001b[39mfrom_code(error_code)\n\u001b[0;32m--> 960\u001b[0m     \u001b[39mraise\u001b[39;00m error_class(parsed_response, operation_name)\n\u001b[1;32m    961\u001b[0m \u001b[39melse\u001b[39;00m:\n\u001b[1;32m    962\u001b[0m     \u001b[39mreturn\u001b[39;00m parsed_response\n",
      "\u001b[0;31mClientError\u001b[0m: An error occurred (InvalidAccessKeyId) when calling the CreateBucket operation: The AWS Access Key Id you provided does not exist in our records."
     ]
    }
   ],
   "source": [
    "import boto3\n",
    "s3 = boto3.client('s3')\n",
    "s3_resource = boto3.resource('s3')\n",
    "bucket = 'emrbuckey'\n",
    "s3_resource.create_bucket(Bucket=bucket)"
   ]
  },
  {
   "cell_type": "code",
   "execution_count": 3,
   "metadata": {
    "collapsed": false
   },
   "outputs": [],
   "source": [
    "filename = 'bootstrap'\n",
    "s3.upload_file(filename, bucket, filename)"
   ]
  },
  {
   "cell_type": "code",
   "execution_count": 6,
   "metadata": {},
   "outputs": [],
   "source": [
    "# jarfile = 'mysql-connector-j-8.0.33.jar'\n",
    "# s3.upload_file(jarfile, bucket, jarfile)"
   ]
  },
  {
   "cell_type": "code",
   "execution_count": null,
   "metadata": {},
   "outputs": [],
   "source": [
    "from urllib.parse import urljoin, urlparse\n",
    "# from datetime import datetime\n",
    "# from bs4 import BeautifulSoup\n",
    "import dataset"
   ]
  },
  {
   "cell_type": "code",
   "execution_count": null,
   "metadata": {},
   "outputs": [],
   "source": [
    "# Connect via database\n",
    "\n",
    "ENDPOINT = 'relational-db.cmzhp3dvx2ii.us-east-1.rds.amazonaws.com'\n",
    "PORT = 3306\n",
    "db_url = \\\n",
    "        'mysql+mysqlconnector://{}:{}@{}:{}/books'.format(\n",
    "                                                'username',\n",
    "                                                'password',\n",
    "                                                ENDPOINT,\n",
    "                                                PORT)\n",
    "# db = dataset.connect(db_url)"
   ]
  },
  {
   "cell_type": "code",
   "execution_count": null,
   "metadata": {},
   "outputs": [],
   "source": [
    "from sqlalchemy import create_engine\n",
    "import pandas as pd\n",
    "\n",
    "# connect to the database\n",
    "engine = create_engine(db_url)\n",
    "df = pd.read_sql_query(\"SELECT * FROM book_info\", engine)\n",
    "\n",
    "# convert the data to parquet\n",
    "df.to_parquet('book_info.parquet')"
   ]
  },
  {
   "cell_type": "code",
   "execution_count": 20,
   "metadata": {},
   "outputs": [
    {
     "ename": "S3UploadFailedError",
     "evalue": "Failed to upload book_info.parquet to emrbuckey/book_info.parquet: An error occurred (AccessDenied) when calling the PutObject operation: Access Denied",
     "output_type": "error",
     "traceback": [
      "\u001b[0;31m---------------------------------------------------------------------------\u001b[0m",
      "\u001b[0;31mClientError\u001b[0m                               Traceback (most recent call last)",
      "File \u001b[0;32m~/opt/anaconda3/lib/python3.9/site-packages/boto3/s3/transfer.py:292\u001b[0m, in \u001b[0;36mS3Transfer.upload_file\u001b[0;34m(self, filename, bucket, key, callback, extra_args)\u001b[0m\n\u001b[1;32m    291\u001b[0m \u001b[39mtry\u001b[39;00m:\n\u001b[0;32m--> 292\u001b[0m     future\u001b[39m.\u001b[39;49mresult()\n\u001b[1;32m    293\u001b[0m \u001b[39m# If a client error was raised, add the backwards compatibility layer\u001b[39;00m\n\u001b[1;32m    294\u001b[0m \u001b[39m# that raises a S3UploadFailedError. These specific errors were only\u001b[39;00m\n\u001b[1;32m    295\u001b[0m \u001b[39m# ever thrown for upload_parts but now can be thrown for any related\u001b[39;00m\n\u001b[1;32m    296\u001b[0m \u001b[39m# client error.\u001b[39;00m\n",
      "File \u001b[0;32m~/opt/anaconda3/lib/python3.9/site-packages/s3transfer/futures.py:103\u001b[0m, in \u001b[0;36mTransferFuture.result\u001b[0;34m(self)\u001b[0m\n\u001b[1;32m     99\u001b[0m \u001b[39mtry\u001b[39;00m:\n\u001b[1;32m    100\u001b[0m     \u001b[39m# Usually the result() method blocks until the transfer is done,\u001b[39;00m\n\u001b[1;32m    101\u001b[0m     \u001b[39m# however if a KeyboardInterrupt is raised we want want to exit\u001b[39;00m\n\u001b[1;32m    102\u001b[0m     \u001b[39m# out of this and propagate the exception.\u001b[39;00m\n\u001b[0;32m--> 103\u001b[0m     \u001b[39mreturn\u001b[39;00m \u001b[39mself\u001b[39;49m\u001b[39m.\u001b[39;49m_coordinator\u001b[39m.\u001b[39;49mresult()\n\u001b[1;32m    104\u001b[0m \u001b[39mexcept\u001b[39;00m \u001b[39mKeyboardInterrupt\u001b[39;00m \u001b[39mas\u001b[39;00m e:\n",
      "File \u001b[0;32m~/opt/anaconda3/lib/python3.9/site-packages/s3transfer/futures.py:266\u001b[0m, in \u001b[0;36mTransferCoordinator.result\u001b[0;34m(self)\u001b[0m\n\u001b[1;32m    265\u001b[0m \u001b[39mif\u001b[39;00m \u001b[39mself\u001b[39m\u001b[39m.\u001b[39m_exception:\n\u001b[0;32m--> 266\u001b[0m     \u001b[39mraise\u001b[39;00m \u001b[39mself\u001b[39m\u001b[39m.\u001b[39m_exception\n\u001b[1;32m    267\u001b[0m \u001b[39mreturn\u001b[39;00m \u001b[39mself\u001b[39m\u001b[39m.\u001b[39m_result\n",
      "File \u001b[0;32m~/opt/anaconda3/lib/python3.9/site-packages/s3transfer/tasks.py:139\u001b[0m, in \u001b[0;36mTask.__call__\u001b[0;34m(self)\u001b[0m\n\u001b[1;32m    138\u001b[0m     \u001b[39mif\u001b[39;00m \u001b[39mnot\u001b[39;00m \u001b[39mself\u001b[39m\u001b[39m.\u001b[39m_transfer_coordinator\u001b[39m.\u001b[39mdone():\n\u001b[0;32m--> 139\u001b[0m         \u001b[39mreturn\u001b[39;00m \u001b[39mself\u001b[39;49m\u001b[39m.\u001b[39;49m_execute_main(kwargs)\n\u001b[1;32m    140\u001b[0m \u001b[39mexcept\u001b[39;00m \u001b[39mException\u001b[39;00m \u001b[39mas\u001b[39;00m e:\n",
      "File \u001b[0;32m~/opt/anaconda3/lib/python3.9/site-packages/s3transfer/tasks.py:162\u001b[0m, in \u001b[0;36mTask._execute_main\u001b[0;34m(self, kwargs)\u001b[0m\n\u001b[1;32m    160\u001b[0m logger\u001b[39m.\u001b[39mdebug(\u001b[39mf\u001b[39m\u001b[39m\"\u001b[39m\u001b[39mExecuting task \u001b[39m\u001b[39m{\u001b[39;00m\u001b[39mself\u001b[39m\u001b[39m}\u001b[39;00m\u001b[39m with kwargs \u001b[39m\u001b[39m{\u001b[39;00mkwargs_to_display\u001b[39m}\u001b[39;00m\u001b[39m\"\u001b[39m)\n\u001b[0;32m--> 162\u001b[0m return_value \u001b[39m=\u001b[39m \u001b[39mself\u001b[39;49m\u001b[39m.\u001b[39;49m_main(\u001b[39m*\u001b[39;49m\u001b[39m*\u001b[39;49mkwargs)\n\u001b[1;32m    163\u001b[0m \u001b[39m# If the task is the final task, then set the TransferFuture's\u001b[39;00m\n\u001b[1;32m    164\u001b[0m \u001b[39m# value to the return value from main().\u001b[39;00m\n",
      "File \u001b[0;32m~/opt/anaconda3/lib/python3.9/site-packages/s3transfer/upload.py:758\u001b[0m, in \u001b[0;36mPutObjectTask._main\u001b[0;34m(self, client, fileobj, bucket, key, extra_args)\u001b[0m\n\u001b[1;32m    757\u001b[0m \u001b[39mwith\u001b[39;00m fileobj \u001b[39mas\u001b[39;00m body:\n\u001b[0;32m--> 758\u001b[0m     client\u001b[39m.\u001b[39;49mput_object(Bucket\u001b[39m=\u001b[39;49mbucket, Key\u001b[39m=\u001b[39;49mkey, Body\u001b[39m=\u001b[39;49mbody, \u001b[39m*\u001b[39;49m\u001b[39m*\u001b[39;49mextra_args)\n",
      "File \u001b[0;32m~/opt/anaconda3/lib/python3.9/site-packages/botocore/client.py:530\u001b[0m, in \u001b[0;36mClientCreator._create_api_method.<locals>._api_call\u001b[0;34m(self, *args, **kwargs)\u001b[0m\n\u001b[1;32m    529\u001b[0m \u001b[39m# The \"self\" in this scope is referring to the BaseClient.\u001b[39;00m\n\u001b[0;32m--> 530\u001b[0m \u001b[39mreturn\u001b[39;00m \u001b[39mself\u001b[39;49m\u001b[39m.\u001b[39;49m_make_api_call(operation_name, kwargs)\n",
      "File \u001b[0;32m~/opt/anaconda3/lib/python3.9/site-packages/botocore/client.py:960\u001b[0m, in \u001b[0;36mBaseClient._make_api_call\u001b[0;34m(self, operation_name, api_params)\u001b[0m\n\u001b[1;32m    959\u001b[0m     error_class \u001b[39m=\u001b[39m \u001b[39mself\u001b[39m\u001b[39m.\u001b[39mexceptions\u001b[39m.\u001b[39mfrom_code(error_code)\n\u001b[0;32m--> 960\u001b[0m     \u001b[39mraise\u001b[39;00m error_class(parsed_response, operation_name)\n\u001b[1;32m    961\u001b[0m \u001b[39melse\u001b[39;00m:\n",
      "\u001b[0;31mClientError\u001b[0m: An error occurred (AccessDenied) when calling the PutObject operation: Access Denied",
      "\nDuring handling of the above exception, another exception occurred:\n",
      "\u001b[0;31mS3UploadFailedError\u001b[0m                       Traceback (most recent call last)",
      "Cell \u001b[0;32mIn[20], line 5\u001b[0m\n\u001b[1;32m      2\u001b[0m file_name \u001b[38;5;241m=\u001b[39m \u001b[38;5;124m'\u001b[39m\u001b[38;5;124mbook_info.parquet\u001b[39m\u001b[38;5;124m'\u001b[39m\n\u001b[1;32m      3\u001b[0m \u001b[38;5;66;03m# Name of the bucket\u001b[39;00m\n\u001b[0;32m----> 5\u001b[0m \u001b[43ms3\u001b[49m\u001b[38;5;241;43m.\u001b[39;49m\u001b[43mupload_file\u001b[49m\u001b[43m(\u001b[49m\u001b[43mfile_name\u001b[49m\u001b[43m,\u001b[49m\u001b[43m \u001b[49m\u001b[43mbucket\u001b[49m\u001b[43m,\u001b[49m\u001b[43m \u001b[49m\u001b[43mfile_name\u001b[49m\u001b[43m)\u001b[49m\n",
      "File \u001b[0;32m~/opt/anaconda3/lib/python3.9/site-packages/boto3/s3/inject.py:143\u001b[0m, in \u001b[0;36mupload_file\u001b[0;34m(self, Filename, Bucket, Key, ExtraArgs, Callback, Config)\u001b[0m\n\u001b[1;32m    108\u001b[0m \u001b[39m\u001b[39m\u001b[39m\"\"\"Upload a file to an S3 object.\u001b[39;00m\n\u001b[1;32m    109\u001b[0m \n\u001b[1;32m    110\u001b[0m \u001b[39mUsage::\u001b[39;00m\n\u001b[0;32m   (...)\u001b[0m\n\u001b[1;32m    140\u001b[0m \u001b[39m    transfer.\u001b[39;00m\n\u001b[1;32m    141\u001b[0m \u001b[39m\"\"\"\u001b[39;00m\n\u001b[1;32m    142\u001b[0m \u001b[39mwith\u001b[39;00m S3Transfer(\u001b[39mself\u001b[39m, Config) \u001b[39mas\u001b[39;00m transfer:\n\u001b[0;32m--> 143\u001b[0m     \u001b[39mreturn\u001b[39;00m transfer\u001b[39m.\u001b[39;49mupload_file(\n\u001b[1;32m    144\u001b[0m         filename\u001b[39m=\u001b[39;49mFilename,\n\u001b[1;32m    145\u001b[0m         bucket\u001b[39m=\u001b[39;49mBucket,\n\u001b[1;32m    146\u001b[0m         key\u001b[39m=\u001b[39;49mKey,\n\u001b[1;32m    147\u001b[0m         extra_args\u001b[39m=\u001b[39;49mExtraArgs,\n\u001b[1;32m    148\u001b[0m         callback\u001b[39m=\u001b[39;49mCallback,\n\u001b[1;32m    149\u001b[0m     )\n",
      "File \u001b[0;32m~/opt/anaconda3/lib/python3.9/site-packages/boto3/s3/transfer.py:298\u001b[0m, in \u001b[0;36mS3Transfer.upload_file\u001b[0;34m(self, filename, bucket, key, callback, extra_args)\u001b[0m\n\u001b[1;32m    293\u001b[0m \u001b[39m# If a client error was raised, add the backwards compatibility layer\u001b[39;00m\n\u001b[1;32m    294\u001b[0m \u001b[39m# that raises a S3UploadFailedError. These specific errors were only\u001b[39;00m\n\u001b[1;32m    295\u001b[0m \u001b[39m# ever thrown for upload_parts but now can be thrown for any related\u001b[39;00m\n\u001b[1;32m    296\u001b[0m \u001b[39m# client error.\u001b[39;00m\n\u001b[1;32m    297\u001b[0m \u001b[39mexcept\u001b[39;00m ClientError \u001b[39mas\u001b[39;00m e:\n\u001b[0;32m--> 298\u001b[0m     \u001b[39mraise\u001b[39;00m S3UploadFailedError(\n\u001b[1;32m    299\u001b[0m         \u001b[39m\"\u001b[39m\u001b[39mFailed to upload \u001b[39m\u001b[39m{}\u001b[39;00m\u001b[39m to \u001b[39m\u001b[39m{}\u001b[39;00m\u001b[39m: \u001b[39m\u001b[39m{}\u001b[39;00m\u001b[39m\"\u001b[39m\u001b[39m.\u001b[39mformat(\n\u001b[1;32m    300\u001b[0m             filename, \u001b[39m'\u001b[39m\u001b[39m/\u001b[39m\u001b[39m'\u001b[39m\u001b[39m.\u001b[39mjoin([bucket, key]), e\n\u001b[1;32m    301\u001b[0m         )\n\u001b[1;32m    302\u001b[0m     )\n",
      "\u001b[0;31mS3UploadFailedError\u001b[0m: Failed to upload book_info.parquet to emrbuckey/book_info.parquet: An error occurred (AccessDenied) when calling the PutObject operation: Access Denied"
     ]
    }
   ],
   "source": [
    "# File to upload\n",
    "file_name = 'book_info.parquet'\n",
    "\n",
    "# Name of the bucket\n",
    "s3.upload_file(file_name, bucket, file_name)\n"
   ]
  },
  {
   "cell_type": "code",
   "execution_count": 3,
   "metadata": {
    "collapsed": false
   },
   "outputs": [],
   "source": [
    "# sudo chmod 400 labsuser.pem"
   ]
  },
  {
   "cell_type": "code",
   "execution_count": null,
   "metadata": {
    "collapsed": false,
    "pycharm": {
     "is_executing": true
    }
   },
   "outputs": [],
   "source": [
    "%%bash\n",
    "killall ssh\n",
    "lsof -ti:9443 | xargs kill -9"
   ]
  },
  {
   "cell_type": "code",
   "execution_count": 1,
   "metadata": {
    "collapsed": false
   },
   "outputs": [],
   "source": [
    "# ssh -i labsuser.pem -NL 8888:localhost:8888 hadoop@ec2-54-227-39-203.compute-1.amazonaws.com"
   ]
  },
  {
   "cell_type": "code",
   "execution_count": 19,
   "metadata": {
    "collapsed": false
   },
   "outputs": [
    {
     "name": "stderr",
     "output_type": "stream",
     "text": [
      "\n",
      "An error occurred (AccessDeniedException) when calling the RunJobFlow operation: User: arn:aws:sts::385606088252:assumed-role/voclabs/user2513084=yuanninghuang@uchicago.edu is not authorized to perform: elasticmapreduce:RunJobFlow on resource: arn:aws:elasticmapreduce:us-east-1:385606088252:cluster/* with an explicit deny in an identity-based policy\n"
     ]
    },
    {
     "ename": "CalledProcessError",
     "evalue": "Command 'b'aws emr create-cluster \\\\\\n    --name \"Spark Cluster\" \\\\\\n    --release-label \"emr-6.2.0\" \\\\\\n    --applications Name=Hadoop Name=Hive Name=JupyterEnterpriseGateway Name=JupyterHub Name=Livy Name=Pig Name=Spark Name=Tez \\\\\\n    --instance-type m5.xlarge \\\\\\n    --instance-count 9 \\\\\\n    --use-default-roles \\\\\\n    --region us-east-1 \\\\\\n    --ec2-attributes KeyName=labsuser-ec2 \\\\\\n    --configurations \\'[{\"Classification\": \"jupyter-s3-conf\", \"Properties\": {\"s3.persistence.enabled\": \"true\", \"s3.persistence.bucket\": \"emrbuckey\"}}]\\'\\n'' returned non-zero exit status 255.",
     "output_type": "error",
     "traceback": [
      "\u001b[0;31m---------------------------------------------------------------------------\u001b[0m",
      "\u001b[0;31mCalledProcessError\u001b[0m                        Traceback (most recent call last)",
      "Cell \u001b[0;32mIn[19], line 1\u001b[0m\n\u001b[0;32m----> 1\u001b[0m \u001b[43mget_ipython\u001b[49m\u001b[43m(\u001b[49m\u001b[43m)\u001b[49m\u001b[38;5;241;43m.\u001b[39;49m\u001b[43mrun_cell_magic\u001b[49m\u001b[43m(\u001b[49m\u001b[38;5;124;43m'\u001b[39;49m\u001b[38;5;124;43mbash\u001b[39;49m\u001b[38;5;124;43m'\u001b[39;49m\u001b[43m,\u001b[49m\u001b[43m \u001b[49m\u001b[38;5;124;43m'\u001b[39;49m\u001b[38;5;124;43m'\u001b[39;49m\u001b[43m,\u001b[49m\u001b[43m \u001b[49m\u001b[38;5;124;43m'\u001b[39;49m\u001b[38;5;124;43maws emr create-cluster \u001b[39;49m\u001b[38;5;130;43;01m\\\\\u001b[39;49;00m\u001b[38;5;130;43;01m\\n\u001b[39;49;00m\u001b[38;5;124;43m    --name \u001b[39;49m\u001b[38;5;124;43m\"\u001b[39;49m\u001b[38;5;124;43mSpark Cluster\u001b[39;49m\u001b[38;5;124;43m\"\u001b[39;49m\u001b[38;5;124;43m \u001b[39;49m\u001b[38;5;130;43;01m\\\\\u001b[39;49;00m\u001b[38;5;130;43;01m\\n\u001b[39;49;00m\u001b[38;5;124;43m    --release-label \u001b[39;49m\u001b[38;5;124;43m\"\u001b[39;49m\u001b[38;5;124;43memr-6.2.0\u001b[39;49m\u001b[38;5;124;43m\"\u001b[39;49m\u001b[38;5;124;43m \u001b[39;49m\u001b[38;5;130;43;01m\\\\\u001b[39;49;00m\u001b[38;5;130;43;01m\\n\u001b[39;49;00m\u001b[38;5;124;43m    --applications Name=Hadoop Name=Hive Name=JupyterEnterpriseGateway Name=JupyterHub Name=Livy Name=Pig Name=Spark Name=Tez \u001b[39;49m\u001b[38;5;130;43;01m\\\\\u001b[39;49;00m\u001b[38;5;130;43;01m\\n\u001b[39;49;00m\u001b[38;5;124;43m    --instance-type m5.xlarge \u001b[39;49m\u001b[38;5;130;43;01m\\\\\u001b[39;49;00m\u001b[38;5;130;43;01m\\n\u001b[39;49;00m\u001b[38;5;124;43m    --instance-count 9 \u001b[39;49m\u001b[38;5;130;43;01m\\\\\u001b[39;49;00m\u001b[38;5;130;43;01m\\n\u001b[39;49;00m\u001b[38;5;124;43m    --use-default-roles \u001b[39;49m\u001b[38;5;130;43;01m\\\\\u001b[39;49;00m\u001b[38;5;130;43;01m\\n\u001b[39;49;00m\u001b[38;5;124;43m    --region us-east-1 \u001b[39;49m\u001b[38;5;130;43;01m\\\\\u001b[39;49;00m\u001b[38;5;130;43;01m\\n\u001b[39;49;00m\u001b[38;5;124;43m    --ec2-attributes KeyName=labsuser-ec2 \u001b[39;49m\u001b[38;5;130;43;01m\\\\\u001b[39;49;00m\u001b[38;5;130;43;01m\\n\u001b[39;49;00m\u001b[38;5;124;43m    --configurations \u001b[39;49m\u001b[38;5;130;43;01m\\'\u001b[39;49;00m\u001b[38;5;124;43m[\u001b[39;49m\u001b[38;5;124;43m{\u001b[39;49m\u001b[38;5;124;43m\"\u001b[39;49m\u001b[38;5;124;43mClassification\u001b[39;49m\u001b[38;5;124;43m\"\u001b[39;49m\u001b[38;5;124;43m: \u001b[39;49m\u001b[38;5;124;43m\"\u001b[39;49m\u001b[38;5;124;43mjupyter-s3-conf\u001b[39;49m\u001b[38;5;124;43m\"\u001b[39;49m\u001b[38;5;124;43m, \u001b[39;49m\u001b[38;5;124;43m\"\u001b[39;49m\u001b[38;5;124;43mProperties\u001b[39;49m\u001b[38;5;124;43m\"\u001b[39;49m\u001b[38;5;124;43m: \u001b[39;49m\u001b[38;5;124;43m{\u001b[39;49m\u001b[38;5;124;43m\"\u001b[39;49m\u001b[38;5;124;43ms3.persistence.enabled\u001b[39;49m\u001b[38;5;124;43m\"\u001b[39;49m\u001b[38;5;124;43m: \u001b[39;49m\u001b[38;5;124;43m\"\u001b[39;49m\u001b[38;5;124;43mtrue\u001b[39;49m\u001b[38;5;124;43m\"\u001b[39;49m\u001b[38;5;124;43m, \u001b[39;49m\u001b[38;5;124;43m\"\u001b[39;49m\u001b[38;5;124;43ms3.persistence.bucket\u001b[39;49m\u001b[38;5;124;43m\"\u001b[39;49m\u001b[38;5;124;43m: \u001b[39;49m\u001b[38;5;124;43m\"\u001b[39;49m\u001b[38;5;124;43memrbuckey\u001b[39;49m\u001b[38;5;124;43m\"\u001b[39;49m\u001b[38;5;124;43m}}]\u001b[39;49m\u001b[38;5;130;43;01m\\'\u001b[39;49;00m\u001b[38;5;130;43;01m\\n\u001b[39;49;00m\u001b[38;5;124;43m'\u001b[39;49m\u001b[43m)\u001b[49m\n",
      "File \u001b[0;32m~/opt/anaconda3/lib/python3.9/site-packages/IPython/core/interactiveshell.py:2475\u001b[0m, in \u001b[0;36mInteractiveShell.run_cell_magic\u001b[0;34m(self, magic_name, line, cell)\u001b[0m\n\u001b[1;32m   2473\u001b[0m \u001b[39mwith\u001b[39;00m \u001b[39mself\u001b[39m\u001b[39m.\u001b[39mbuiltin_trap:\n\u001b[1;32m   2474\u001b[0m     args \u001b[39m=\u001b[39m (magic_arg_s, cell)\n\u001b[0;32m-> 2475\u001b[0m     result \u001b[39m=\u001b[39m fn(\u001b[39m*\u001b[39;49margs, \u001b[39m*\u001b[39;49m\u001b[39m*\u001b[39;49mkwargs)\n\u001b[1;32m   2477\u001b[0m \u001b[39m# The code below prevents the output from being displayed\u001b[39;00m\n\u001b[1;32m   2478\u001b[0m \u001b[39m# when using magics with decodator @output_can_be_silenced\u001b[39;00m\n\u001b[1;32m   2479\u001b[0m \u001b[39m# when the last Python token in the expression is a ';'.\u001b[39;00m\n\u001b[1;32m   2480\u001b[0m \u001b[39mif\u001b[39;00m \u001b[39mgetattr\u001b[39m(fn, magic\u001b[39m.\u001b[39mMAGIC_OUTPUT_CAN_BE_SILENCED, \u001b[39mFalse\u001b[39;00m):\n",
      "File \u001b[0;32m~/opt/anaconda3/lib/python3.9/site-packages/IPython/core/magics/script.py:153\u001b[0m, in \u001b[0;36mScriptMagics._make_script_magic.<locals>.named_script_magic\u001b[0;34m(line, cell)\u001b[0m\n\u001b[1;32m    151\u001b[0m \u001b[39melse\u001b[39;00m:\n\u001b[1;32m    152\u001b[0m     line \u001b[39m=\u001b[39m script\n\u001b[0;32m--> 153\u001b[0m \u001b[39mreturn\u001b[39;00m \u001b[39mself\u001b[39;49m\u001b[39m.\u001b[39;49mshebang(line, cell)\n",
      "File \u001b[0;32m~/opt/anaconda3/lib/python3.9/site-packages/IPython/core/magics/script.py:305\u001b[0m, in \u001b[0;36mScriptMagics.shebang\u001b[0;34m(self, line, cell)\u001b[0m\n\u001b[1;32m    300\u001b[0m \u001b[39mif\u001b[39;00m args\u001b[39m.\u001b[39mraise_error \u001b[39mand\u001b[39;00m p\u001b[39m.\u001b[39mreturncode \u001b[39m!=\u001b[39m \u001b[39m0\u001b[39m:\n\u001b[1;32m    301\u001b[0m     \u001b[39m# If we get here and p.returncode is still None, we must have\u001b[39;00m\n\u001b[1;32m    302\u001b[0m     \u001b[39m# killed it but not yet seen its return code. We don't wait for it,\u001b[39;00m\n\u001b[1;32m    303\u001b[0m     \u001b[39m# in case it's stuck in uninterruptible sleep. -9 = SIGKILL\u001b[39;00m\n\u001b[1;32m    304\u001b[0m     rc \u001b[39m=\u001b[39m p\u001b[39m.\u001b[39mreturncode \u001b[39mor\u001b[39;00m \u001b[39m-\u001b[39m\u001b[39m9\u001b[39m\n\u001b[0;32m--> 305\u001b[0m     \u001b[39mraise\u001b[39;00m CalledProcessError(rc, cell)\n",
      "\u001b[0;31mCalledProcessError\u001b[0m: Command 'b'aws emr create-cluster \\\\\\n    --name \"Spark Cluster\" \\\\\\n    --release-label \"emr-6.2.0\" \\\\\\n    --applications Name=Hadoop Name=Hive Name=JupyterEnterpriseGateway Name=JupyterHub Name=Livy Name=Pig Name=Spark Name=Tez \\\\\\n    --instance-type m5.xlarge \\\\\\n    --instance-count 9 \\\\\\n    --use-default-roles \\\\\\n    --region us-east-1 \\\\\\n    --ec2-attributes KeyName=labsuser-ec2 \\\\\\n    --configurations \\'[{\"Classification\": \"jupyter-s3-conf\", \"Properties\": {\"s3.persistence.enabled\": \"true\", \"s3.persistence.bucket\": \"emrbuckey\"}}]\\'\\n'' returned non-zero exit status 255."
     ]
    }
   ],
   "source": [
    "%%bash\n",
    "aws emr create-cluster \\\n",
    "    --name \"Spark Cluster\" \\\n",
    "    --release-label \"emr-6.2.0\" \\\n",
    "    --applications Name=Hadoop Name=Hive Name=JupyterEnterpriseGateway Name=JupyterHub Name=Livy Name=Pig Name=Spark Name=Tez \\\n",
    "    --instance-type m5.xlarge \\\n",
    "    --instance-count 9 \\\n",
    "    --use-default-roles \\\n",
    "    --region us-east-1 \\\n",
    "    --ec2-attributes KeyName=labsuser-ec2 \\\n",
    "    --configurations '[{\"Classification\": \"jupyter-s3-conf\", \"Properties\": {\"s3.persistence.enabled\": \"true\", \"s3.persistence.bucket\": \"emrbuckey\"}}]'"
   ]
  },
  {
   "cell_type": "code",
   "execution_count": null,
   "metadata": {
    "collapsed": false
   },
   "outputs": [],
   "source": [
    "# ssh -i labsuser.pem -NL 9443:localhost:9443 hadoop@ec2-3-91-38-132.compute-1.amazonaws.com"
   ]
  }
 ],
 "metadata": {
  "kernelspec": {
   "display_name": "Python 3.9.12 ('base')",
   "language": "python",
   "name": "python3"
  },
  "language_info": {
   "codemirror_mode": {
    "name": "ipython",
    "version": 3
   },
   "file_extension": ".py",
   "mimetype": "text/x-python",
   "name": "python",
   "nbconvert_exporter": "python",
   "pygments_lexer": "ipython3",
   "version": "3.9.12"
  },
  "vscode": {
   "interpreter": {
    "hash": "8da593020269d3b8f2f89629b67a40e1602e1b19a7674d304503744e42ece518"
   }
  }
 },
 "nbformat": 4,
 "nbformat_minor": 0
}
